2025-09-22 10:15:37.495 | No changes detected
2025-09-22 10:15:38.786 | Operations to perform:
2025-09-22 10:15:38.786 |   Apply all migrations: accounts, admin, auth, contenttypes, sessions, token_blacklist
2025-09-22 10:15:38.795 | Running migrations:
2025-09-22 10:15:38.819 | Traceback (most recent call last):
2025-09-22 10:15:38.819 |   File "/usr/local/lib/python3.11/site-packages/django/db/backends/utils.py", line 103, in _execute
2025-09-22 10:15:38.819 |     return self.cursor.execute(sql)
2025-09-22 10:15:38.819 |            ^^^^^^^^^^^^^^^^^^^^^^^^
2025-09-22 10:15:38.819 |   File "/usr/local/lib/python3.11/site-packages/django/db/backends/sqlite3/base.py", line 356, in execute
2025-09-22 10:15:38.819 |     return super().execute(query)
2025-09-22 10:15:38.819 |            ^^^^^^^^^^^^^^^^^^^^^^
2025-09-22 10:15:38.819 | sqlite3.OperationalError: foreign key mismatch - "token_blacklist_outstandingtoken" referencing "accounts_usuario"
2025-09-22 10:15:38.819 | 
2025-09-22 10:15:38.819 | The above exception was the direct cause of the following exception:
2025-09-22 10:15:38.819 | 
2025-09-22 10:15:38.819 | Traceback (most recent call last):
2025-09-22 10:15:38.819 |   File "/app/manage.py", line 22, in <module>
2025-09-22 10:15:38.821 |     main()
2025-09-22 10:15:38.821 |   File "/app/manage.py", line 18, in main
2025-09-22 10:15:38.823 |     execute_from_command_line(sys.argv)
2025-09-22 10:15:38.823 |   File "/usr/local/lib/python3.11/site-packages/django/core/management/__init__.py", line 442, in execute_from_command_line
2025-09-22 10:15:38.824 |     utility.execute()
2025-09-22 10:15:38.824 |   File "/usr/local/lib/python3.11/site-packages/django/core/management/__init__.py", line 436, in execute
2025-09-22 10:15:38.825 |     self.fetch_command(subcommand).run_from_argv(self.argv)
2025-09-22 10:15:38.825 |   File "/usr/local/lib/python3.11/site-packages/django/core/management/base.py", line 416, in run_from_argv
2025-09-22 10:15:38.825 |     self.execute(*args, **cmd_options)
2025-09-22 10:15:38.825 |   File "/usr/local/lib/python3.11/site-packages/django/core/management/base.py", line 460, in execute
2025-09-22 10:15:38.825 |     output = self.handle(*args, **options)
2025-09-22 10:15:38.825 |              ^^^^^^^^^^^^^^^^^^^^^^^^^^^^^
2025-09-22 10:15:38.825 |   File "/usr/local/lib/python3.11/site-packages/django/core/management/base.py", line 107, in wrapper
2025-09-22 10:15:38.825 |     res = handle_func(*args, **kwargs)
2025-09-22 10:15:38.825 |           ^^^^^^^^^^^^^^^^^^^^^^^^^^^^
2025-09-22 10:15:38.825 |   File "/usr/local/lib/python3.11/site-packages/django/core/management/commands/migrate.py", line 353, in handle
2025-09-22 10:15:38.826 |     post_migrate_state = executor.migrate(
2025-09-22 10:15:38.826 |                          ^^^^^^^^^^^^^^^^^
2025-09-22 10:15:38.826 |   File "/usr/local/lib/python3.11/site-packages/django/db/migrations/executor.py", line 135, in migrate
2025-09-22 10:15:38.826 |     state = self._migrate_all_forwards(
2025-09-22 10:15:38.826 |             ^^^^^^^^^^^^^^^^^^^^^^^^^^^
2025-09-22 10:15:38.826 |   File "/usr/local/lib/python3.11/site-packages/django/db/migrations/executor.py", line 167, in _migrate_all_forwards
2025-09-22 10:15:38.827 |     state = self.apply_migration(
2025-09-22 10:15:38.827 |             ^^^^^^^^^^^^^^^^^^^^^
2025-09-22 10:15:38.827 |   File "/usr/local/lib/python3.11/site-packages/django/db/migrations/executor.py", line 252, in apply_migration
2025-09-22 10:15:38.827 |     with self.connection.schema_editor(
2025-09-22 10:15:38.827 |   File "/usr/local/lib/python3.11/site-packages/django/db/backends/sqlite3/schema.py", line 39, in __exit__
2025-09-22 10:15:38.827 |     self.connection.check_constraints()
2025-09-22 10:15:38.827 |   File "/usr/local/lib/python3.11/site-packages/django/db/backends/sqlite3/base.py", line 273, in check_constraints
2025-09-22 10:15:38.827 |     violations = cursor.execute("PRAGMA foreign_key_check").fetchall()
2025-09-22 10:15:38.827 |                  ^^^^^^^^^^^^^^^^^^^^^^^^^^^^^^^^^^^^^^^^^^
2025-09-22 10:15:38.827 |   File "/usr/local/lib/python3.11/site-packages/django/db/backends/utils.py", line 122, in execute
2025-09-22 10:15:38.827 |     return super().execute(sql, params)
2025-09-22 10:15:38.828 |            ^^^^^^^^^^^^^^^^^^^^^^^^^^^^
2025-09-22 10:15:38.828 |   File "/usr/local/lib/python3.11/site-packages/django/db/backends/utils.py", line 79, in execute
2025-09-22 10:15:38.828 |     return self._execute_with_wrappers(
2025-09-22 10:15:38.828 |            ^^^^^^^^^^^^^^^^^^^^^^^^^^^^
2025-09-22 10:15:38.828 |   File "/usr/local/lib/python3.11/site-packages/django/db/backends/utils.py", line 92, in _execute_with_wrappers
2025-09-22 10:15:38.828 |     return executor(sql, params, many, context)
2025-09-22 10:15:38.828 |            ^^^^^^^^^^^^^^^^^^^^^^^^^^^^^^^^^^^^
2025-09-22 10:15:38.828 |   File "/usr/local/lib/python3.11/site-packages/django/db/backends/utils.py", line 100, in _execute
2025-09-22 10:15:38.828 |     with self.db.wrap_database_errors:
2025-09-22 10:15:38.828 |   File "/usr/local/lib/python3.11/site-packages/django/db/utils.py", line 91, in __exit__
2025-09-22 10:15:38.828 |     raise dj_exc_value.with_traceback(traceback) from exc_value
2025-09-22 10:15:38.828 |   File "/usr/local/lib/python3.11/site-packages/django/db/backends/utils.py", line 103, in _execute
2025-09-22 10:15:38.828 |     return self.cursor.execute(sql)
2025-09-22 10:15:38.828 |            ^^^^^^^^^^^^^^^^^^^^^^^^
2025-09-22 10:15:38.828 |   File "/usr/local/lib/python3.11/site-packages/django/db/backends/sqlite3/base.py", line 356, in execute
2025-09-22 10:15:38.828 |     return super().execute(query)
2025-09-22 10:15:38.828 |            ^^^^^^^^^^^^^^^^^^^^^^
2025-09-22 10:15:38.828 | django.db.utils.OperationalError: foreign key mismatch - "token_blacklist_outstandingtoken" referencing "accounts_usuario"
2025-09-22 10:15:38.934 |   Applying token_blacklist.0001_initial...